<?xml version="1.0" ?>
<!-- =================================================================================== -->
<!-- |    This document was autogenerated by xacro from src/third_party/flexiv_ros2/flexiv_description/urdf/rizon.urdf.xacro | -->
<!-- |    EDITING THIS FILE BY HAND IS NOT RECOMMENDED                                 | -->
<!-- =================================================================================== -->
<robot name="rizon">
  <!-- base link -->
  <link name="grav_base_link">
    <inertial>
      <origin rpy="0 0 0" xyz="0 0 0.057"/>
      <mass value="1.186"/>
      <inertia ixx="3E-3" ixy="0" ixz="0" iyy="3E-3" iyz="-0" izz="1E-3"/>
    </inertial>
    <visual>
      <origin rpy="0 0 1.5707963267948966" xyz="0 0 0"/>
      <geometry>
        <mesh filename="package://flexiv_description/meshes/Grav/visual/base.stl" scale="0.001 0.001 0.001"/>
      </geometry>
      <material name="flexiv_black"/>
    </visual>
    <collision>
      <origin rpy="0 0 1.5707963267948966" xyz="0 0 0"/>
      <geometry>
        <mesh filename="package://flexiv_description/meshes/Grav/collision/base.stl" scale="0.001 0.001 0.001"/>
      </geometry>
    </collision>
  </link>
  <!-- left finger links -->
  <link name="left_outer_bar">
    <inertial>
      <origin rpy="0 0 0" xyz="0 0 0.029"/>
      <mass value="1E-4"/>
      <inertia ixx="1E-7" ixy="0" ixz="0" iyy="1E-7" iyz="0" izz="1E-7"/>
    </inertial>
    <visual>
      <origin rpy="0 0 1.5707963267948966" xyz="0 0 0"/>
      <geometry>
        <mesh filename="package://flexiv_description/meshes/Grav/visual/outer_bar.stl" scale="0.001 0.001 0.001"/>
      </geometry>
      <material name="flexiv_black"/>
    </visual>
    <collision>
      <origin rpy="0 0 1.5707963267948966" xyz="0 0 0"/>
      <geometry>
        <mesh filename="package://flexiv_description/meshes/Grav/collision/outer_bar.stl" scale="0.001 0.001 0.001"/>
      </geometry>
    </collision>
  </link>
  <link name="left_inner_bar">
    <inertial>
      <origin rpy="0 0 0" xyz="0 0 0.029"/>
      <mass value="1E-4"/>
      <inertia ixx="1E-7" ixy="0" ixz="0" iyy="1E-7" iyz="0" izz="1E-7"/>
    </inertial>
    <visual>
      <origin rpy="0 0 1.5707963267948966" xyz="0 0 0"/>
      <geometry>
        <mesh filename="package://flexiv_description/meshes/Grav/visual/inner_bar.stl" scale="0.001 0.001 0.001"/>
      </geometry>
      <material name="flexiv_black"/>
    </visual>
    <collision>
      <origin rpy="0 0 1.5707963267948966" xyz="0 0 0"/>
      <geometry>
        <mesh filename="package://flexiv_description/meshes/Grav/collision/inner_bar.stl" scale="0.001 0.001 0.001"/>
      </geometry>
    </collision>
  </link>
  <link name="left_finger_mount">
    <inertial>
      <origin rpy="0 0 0" xyz="0 0 0"/>
      <mass value="1E-4"/>
      <inertia ixx="1E-7" ixy="0" ixz="0" iyy="1E-7" iyz="0" izz="1E-7"/>
    </inertial>
    <visual>
      <origin rpy="0 0 1.5707963267948966" xyz="0 0 0"/>
      <geometry>
        <mesh filename="package://flexiv_description/meshes/Grav/visual/finger_mount.stl" scale="0.001 0.001 0.001"/>
      </geometry>
      <material name="flexiv_black"/>
    </visual>
  </link>
  <link name="left_finger_tip">
    <inertial>
      <origin rpy="0 0 0" xyz="0 0 0"/>
      <mass value="0"/>
      <inertia ixx="0" ixy="0" ixz="0" iyy="0" iyz="0" izz="0"/>
    </inertial>
    <visual>
      <origin rpy="0 0 1.5707963267948966" xyz="0 0 0"/>
      <geometry>
        <mesh filename="package://flexiv_description/meshes/Grav/visual/finger_tip.obj" scale="0.001 0.001 0.001"/>
      </geometry>
    </visual>
    <collision>
      <origin rpy="0 0 1.5707963267948966" xyz="0 0 0"/>
      <geometry>
        <mesh filename="package://flexiv_description/meshes/Grav/collision/finger_tip.stl" scale="0.001 0.001 0.001"/>
      </geometry>
    </collision>
  </link>
  <!-- right finger links -->
  <link name="right_outer_bar">
    <inertial>
      <origin rpy="0 0 0" xyz="0 0 0.029"/>
      <mass value="1E-4"/>
      <inertia ixx="1E-7" ixy="0" ixz="0" iyy="1E-7" iyz="0" izz="1E-7"/>
    </inertial>
    <visual>
      <origin rpy="0 0 1.5707963267948966" xyz="0 0 0"/>
      <geometry>
        <mesh filename="package://flexiv_description/meshes/Grav/visual/outer_bar.stl" scale="0.001 0.001 0.001"/>
      </geometry>
      <material name="flexiv_black"/>
    </visual>
    <collision>
      <origin rpy="0 0 1.5707963267948966" xyz="0 0 0"/>
      <geometry>
        <mesh filename="package://flexiv_description/meshes/Grav/collision/outer_bar.stl" scale="0.001 0.001 0.001"/>
      </geometry>
    </collision>
  </link>
  <link name="right_inner_bar">
    <inertial>
      <origin rpy="0 0 0" xyz="0 0 0.029"/>
      <mass value="1E-4"/>
      <inertia ixx="1E-7" ixy="0" ixz="0" iyy="1E-7" iyz="0" izz="1E-7"/>
    </inertial>
    <visual>
      <origin rpy="0 0 1.5707963267948966" xyz="0 0 0"/>
      <geometry>
        <mesh filename="package://flexiv_description/meshes/Grav/visual/inner_bar.stl" scale="0.001 0.001 0.001"/>
      </geometry>
      <material name="flexiv_black"/>
    </visual>
    <collision>
      <origin rpy="0 0 1.5707963267948966" xyz="0 0 0"/>
      <geometry>
        <mesh filename="package://flexiv_description/meshes/Grav/collision/inner_bar.stl" scale="0.001 0.001 0.001"/>
      </geometry>
    </collision>
  </link>
  <link name="right_finger_mount">
    <inertial>
      <origin rpy="0 0 0" xyz="0 0 0"/>
      <mass value="1E-4"/>
      <inertia ixx="1E-7" ixy="0" ixz="0" iyy="1E-7" iyz="0" izz="1E-7"/>
    </inertial>
    <visual>
      <origin rpy="0 0 1.5707963267948966" xyz="0 0 0"/>
      <geometry>
        <mesh filename="package://flexiv_description/meshes/Grav/visual/finger_mount.stl" scale="0.001 0.001 0.001"/>
      </geometry>
      <material name="flexiv_black"/>
    </visual>
  </link>
  <link name="right_finger_tip">
    <inertial>
      <origin rpy="0 0 0" xyz="0 0 0"/>
      <mass value="0"/>
      <inertia ixx="0" ixy="0" ixz="0" iyy="0" iyz="0" izz="0"/>
    </inertial>
    <visual>
      <origin rpy="0 0 1.5707963267948966" xyz="0 0 0"/>
      <geometry>
        <mesh filename="package://flexiv_description/meshes/Grav/visual/finger_tip.obj" scale="0.001 0.001 0.001"/>
      </geometry>
    </visual>
    <collision>
      <origin rpy="0 0 1.5707963267948966" xyz="0 0 0"/>
      <geometry>
        <mesh filename="package://flexiv_description/meshes/Grav/collision/finger_tip.stl" scale="0.001 0.001 0.001"/>
      </geometry>
    </collision>
  </link>
  <!-- TCP links -->
  <link name="grav_tcp">
    <!-- open finger, used by RCA -->
    <inertial>
      <origin rpy="0 0 0" xyz="0 0 0"/>
      <mass value="0"/>
      <inertia ixx="0" ixy="0" ixz="0" iyy="0" iyz="0" izz="0"/>
    </inertial>
  </link>
  <link name="closed_fingers_tcp">
    <inertial>
      <origin rpy="0 0 0" xyz="0 0 0"/>
      <mass value="0"/>
      <inertia ixx="0" ixy="0" ixz="0" iyy="0" iyz="0" izz="0"/>
    </inertial>
  </link>
  <link name="left_finger_tcp">
    <inertial>
      <origin rpy="0 0 0" xyz="0 0 0"/>
      <mass value="0"/>
      <inertia ixx="0" ixy="0" ixz="0" iyy="0" iyz="0" izz="0"/>
    </inertial>
  </link>
  <link name="right_finger_tcp">
    <inertial>
      <origin rpy="0 0 0" xyz="0 0 0"/>
      <mass value="0"/>
      <inertia ixx="0" ixy="0" ixz="0" iyy="0" iyz="0" izz="0"/>
    </inertial>
  </link>
  <!-- JOINTS -->
  <joint name="open_fingers_tcp_joint" type="fixed">
    <origin rpy="0 0 0" xyz="0 0 0.15"/>
    <parent link="grav_base_link"/>
    <child link="grav_tcp"/>
    <axis xyz="0 0 1"/>
  </joint>
  <joint name="closed_fingers_tcp_joint" type="fixed">
    <origin rpy="0 0 0" xyz="0 0 0.20"/>
    <parent link="grav_base_link"/>
    <child link="closed_fingers_tcp"/>
    <axis xyz="0 0 1"/>
  </joint>
  <!-- left finger joints -->
  <joint name="left_outer_knuckle_joint" type="revolute">
    <origin rpy="0 0 0" xyz="0 -0.0325 0.0825"/>
    <parent link="grav_base_link"/>
    <child link="left_outer_bar"/>
    <axis xyz="1 0 0"/>
    <limit effort="0" lower="-0.155" upper="0.7854" velocity="2.0"/>
    <mimic joint="finger_width_joint" multiplier="9.404" offset="-0.155"/>
  </joint>
  <joint name="left_inner_knuckle_joint" type="revolute">
    <origin rpy="0 0 0" xyz="0 -0.0165 0.0995"/>
    <parent link="grav_base_link"/>
    <child link="left_inner_bar"/>
    <axis xyz="1 0 0"/>
    <limit effort="0" lower="-0.155" upper="0.7854" velocity="2.0"/>
    <mimic joint="finger_width_joint" multiplier="9.404" offset="-0.155"/>
  </joint>
  <joint name="left_inner_finger_joint" type="revolute">
    <origin rpy="0 0 0" xyz="0 0 0.058"/>
    <parent link="left_outer_bar"/>
    <child link="left_finger_mount"/>
    <axis xyz="1 0 0"/>
    <limit effort="0" lower="-0.7854" upper="0.155" velocity="2.0"/>
    <mimic joint="finger_width_joint" multiplier="-9.404" offset="0.155"/>
  </joint>
  <joint name="left_inner_finger_pad_joint" type="fixed">
    <origin rpy="0 0 0" xyz="0 0.010 0.0235"/>
    <parent link="left_finger_mount"/>
    <child link="left_finger_tip"/>
    <axis xyz="0 0 1"/>
  </joint>
  <joint name="left_finger_tcp_joint" type="fixed">
    <origin rpy="0 0 0" xyz="0 0.0135 0.036"/>
    <parent link="left_finger_tip"/>
    <child link="left_finger_tcp"/>
    <axis xyz="0 0 1"/>
  </joint>
  <!-- right finger joints -->
  <joint name="right_outer_knuckle_joint" type="revolute">
    <origin rpy="0 0 3.141592653589793" xyz="0 0.0325 0.0825"/>
    <parent link="grav_base_link"/>
    <child link="right_outer_bar"/>
    <axis xyz="1 0 0"/>
    <limit effort="0" lower="-0.155" upper="0.7854" velocity="2.0"/>
    <mimic joint="finger_width_joint" multiplier="9.404" offset="-0.155"/>
  </joint>
  <joint name="right_inner_knuckle_joint" type="revolute">
    <origin rpy="0 0 3.141592653589793" xyz="0 0.0165 0.0995"/>
    <parent link="grav_base_link"/>
    <child link="right_inner_bar"/>
    <axis xyz="1 0 0"/>
    <limit effort="0" lower="-0.155" upper="0.7854" velocity="2.0"/>
    <mimic joint="finger_width_joint" multiplier="9.404" offset="-0.155"/>
  </joint>
  <joint name="right_inner_finger_joint" type="revolute">
    <origin rpy="0 0 0" xyz="0 0 0.058"/>
    <parent link="right_outer_bar"/>
    <child link="right_finger_mount"/>
    <axis xyz="1 0 0"/>
    <limit effort="0" lower="-0.7854" upper="0.155" velocity="2.0"/>
    <mimic joint="finger_width_joint" multiplier="-9.404" offset="0.155"/>
  </joint>
  <joint name="right_inner_finger_pad_joint" type="fixed">
    <origin rpy="0 0 0" xyz="0 0.010 0.0235"/>
    <parent link="right_finger_mount"/>
    <child link="right_finger_tip"/>
    <axis xyz="0 0 1"/>
  </joint>
  <joint name="right_finger_tcp_joint" type="fixed">
    <origin rpy="0 0 0" xyz="0 0.0135 0.036"/>
    <parent link="right_finger_tip"/>
    <child link="right_finger_tcp"/>
    <axis xyz="0 0 1"/>
  </joint>
  <!--
  Control joint.
  Should we replace this with transmission?
  Note: This virtual joint should be prismatic,
        but it must be revolute to match the mimic joint.
        The unused link cannot have 0 mass.
  -->
  <joint name="finger_width_joint" type="revolute">
    <origin rpy="0 0 0" xyz="0 0 0"/>
    <parent link="grav_base_link"/>
    <child link="unused_finger_width_link"/>
    <axis xyz="1 0 0"/>
    <limit effort="80" lower="0" upper="0.100" velocity="2.0"/>
  </joint>
  <link name="unused_finger_width_link">
    <inertial>
      <origin rpy="0 0 0" xyz="0 0 0"/>
      <mass value="1E-4"/>
      <inertia ixx="1E-7" ixy="0" ixz="0" iyy="1E-7" iyz="0" izz="1E-7"/>
    </inertial>
  </link>
  <!-- Connect the gripper to the robot flange link -->
  <joint name="gripper_base_joint" type="fixed">
    <origin rpy="0 0 0" xyz="0 0 0"/>
    <parent link="flange"/>
    <child link="grav_base_link"/>
  </joint>
  <!-- materials -->
  <material name="flexiv_black">
    <color rgba="0.22 0.22 0.22 1"/>
  </material>
  <!-- JOINTS-->
  <joint name="base_joint" type="fixed">
    <parent link="world"/>
    <child link="base_link"/>
    <origin rpy="0.0 0.0 0.0" xyz="0.0 0.0 0.0"/>
  </joint>
  <joint name="joint1" type="revolute">
    <parent link="base_link"/>
    <child link="link1"/>
    <origin rpy="0 0 -3.141592653589793" xyz="0.0 0.0 0.155"/>
    <axis xyz="0 0 1"/>
    <limit effort="123" lower="-2.8798" upper="2.8798" velocity="2.0944"/>
    <safety_controller k_position="100.0" k_velocity="40.0" soft_lower_limit="-2.7925" soft_upper_limit="2.7925"/>
  </joint>
  <joint name="joint2" type="revolute">
    <parent link="link1"/>
    <child link="link2"/>
    <origin rpy="0 0 0" xyz="0.0 0.03 0.210"/>
    <axis xyz="0 1 0"/>
    <limit effort="123" lower="-2.3562" upper="2.3562" velocity="2.0944"/>
    <safety_controller k_position="100.0" k_velocity="40.0" soft_lower_limit="-2.2689" soft_upper_limit="2.2689"/>
  </joint>
  <joint name="joint3" type="revolute">
    <parent link="link2"/>
    <child link="link3"/>
    <origin rpy="0 0 0" xyz="0.0 0.035 0.205"/>
    <axis xyz="0 0 1"/>
    <limit effort="64" lower="-3.0543" upper="3.0543" velocity="2.4435"/>
    <safety_controller k_position="100.0" k_velocity="40.0" soft_lower_limit="-2.9671" soft_upper_limit="2.9671"/>
  </joint>
  <joint name="joint4" type="revolute">
    <parent link="link3"/>
    <child link="link4"/>
    <origin rpy="0 0 -3.141592653589793" xyz="-0.02 -0.03 0.19"/>
    <axis xyz="0 1 0"/>
    <limit effort="64" lower="-1.9548" upper="2.7751" velocity="2.4435"/>
    <safety_controller k_position="100.0" k_velocity="40.0" soft_lower_limit="-1.8675" soft_upper_limit="2.6878"/>
  </joint>
  <joint name="joint5" type="revolute">
    <parent link="link4"/>
    <child link="link5"/>
    <origin rpy="0 0 -3.141592653589793" xyz="-0.02 0.025 0.195"/>
    <axis xyz="0 0 1"/>
    <limit effort="39" lower="-3.0543" upper="3.0543" velocity="4.8869"/>
    <safety_controller k_position="100.0" k_velocity="40.0" soft_lower_limit="-2.9671" soft_upper_limit="2.9671"/>
  </joint>
  <joint name="joint6" type="revolute">
    <parent link="link5"/>
    <child link="link6"/>
    <origin rpy="0 0 0" xyz="0.0 0.03 0.19"/>
    <axis xyz="0 1 0"/>
    <limit effort="39" lower="-1.4835" upper="4.6251" velocity="4.8869"/>
    <safety_controller k_position="100.0" k_velocity="40.0" soft_lower_limit="-1.3963" soft_upper_limit="4.5379"/>
  </joint>
  <joint name="joint7" type="revolute">
    <parent link="link6"/>
    <child link="link7"/>
    <origin rpy="0 -1.5707963267948966 0" xyz="-0.015 0.073 0.11"/>
    <axis xyz="0 0 1"/>
    <limit effort="39" lower="-3.0543" upper="3.0543" velocity="4.8869"/>
    <safety_controller k_position="100.0" k_velocity="40.0" soft_lower_limit="-2.9671" soft_upper_limit="2.9671"/>
  </joint>
  <joint name="link7_to_flange" type="fixed">
    <parent link="link7"/>
    <child link="flange"/>
    <origin rpy="0 0 -3.141592653589793" xyz="0.0 0.0 0.124"/>
  </joint>
  <!-- LINKS -->
  <link name="world">
    </link>
  <link name="base_link">
    <inertial>
      <mass value="3.8"/>
      <origin rpy="0 0 0" xyz="0.0 -0.0 0.09"/>
      <inertia ixx="0.02" ixy="0.0" ixz="0.0" iyy="0.02" iyz="0.0" izz="0.01"/>
    </inertial>
    <visual name="shell">
      <origin rpy="0 0 0" xyz="0 0 0"/>
      <geometry>
        <mesh filename="package://flexiv_description/meshes/Rizon4s/visual/link0.obj"/>
      </geometry>
    </visual>
    <collision name="convex_mesh">
      <origin rpy="0 0 0" xyz="0 0 0"/>
      <geometry>
        <mesh filename="package://flexiv_description/meshes/Rizon4s/collision/link0.stl"/>
      </geometry>
    </collision>
    <workspace>
      <origin rpy="0 0 0" xyz="0 0 0.365"/>
      <geometry>
        <sphere radius="0.890"/>
      </geometry>
    </workspace>
  </link>
  <link name="link1">
    <inertial>
      <mass value="3.6"/>
      <origin rpy="0 0 0" xyz="0.0 0.0 0.15"/>
      <inertia ixx="0.03" ixy="0.0" ixz="0.0" iyy="0.03" iyz="0.0" izz="0.01"/>
    </inertial>
    <visual name="shell">
      <origin rpy="0 0 0" xyz="0 0 0"/>
      <geometry>
        <mesh filename="package://flexiv_description/meshes/Rizon4s/visual/link1.obj"/>
      </geometry>
    </visual>
    <visual name="ring">
      <origin rpy="0 0 0" xyz="0 0 -0.0025"/>
      <geometry>
        <mesh filename="package://flexiv_description/meshes/Rizon4s/visual/ring.obj" scale="0.062 0.062 0.002"/>
      </geometry>
    </visual>
    <collision name="convex_mesh">
      <origin rpy="0 0 0" xyz="0 0 0"/>
      <geometry>
        <mesh filename="package://flexiv_description/meshes/Rizon4s/collision/link1.stl"/>
      </geometry>
    </collision>
  </link>
  <link name="link2">
    <inertial>
      <mass value="2.7"/>
      <origin rpy="0 0 0" xyz="-0.0 0.04 0.1"/>
      <inertia ixx="0.02" ixy="0.0" ixz="0.0" iyy="0.02" iyz="-0.0003" izz="0.004"/>
    </inertial>
    <visual name="shell">
      <origin rpy="0 0 0" xyz="0 0 0"/>
      <geometry>
        <mesh filename="package://flexiv_description/meshes/Rizon4s/visual/link2.obj"/>
      </geometry>
    </visual>
    <visual name="ring">
      <origin rpy="1.5707963267948966 0 0" xyz="0 -0.0025 0"/>
      <geometry>
        <mesh filename="package://flexiv_description/meshes/Rizon4s/visual/ring.obj" scale="0.062 0.062 0.002"/>
      </geometry>
    </visual>
    <collision name="convex_mesh">
      <origin rpy="0 0 0" xyz="0 0 0"/>
      <geometry>
        <mesh filename="package://flexiv_description/meshes/Rizon4s/collision/link2.stl"/>
      </geometry>
    </collision>
  </link>
  <link name="link3">
    <inertial>
      <mass value="2.4"/>
      <origin rpy="0 0 0" xyz="-0.01 -0.0 0.14"/>
      <inertia ixx="0.01" ixy="0.0" ixz="-0.001" iyy="0.01" iyz="-0.0007" izz="0.004"/>
    </inertial>
    <visual name="shell">
      <origin rpy="0 0 0" xyz="0 0 0"/>
      <geometry>
        <mesh filename="package://flexiv_description/meshes/Rizon4s/visual/link3.obj"/>
      </geometry>
    </visual>
    <visual name="ring">
      <origin rpy="0 0 0" xyz="0 0 -0.0025"/>
      <geometry>
        <mesh filename="package://flexiv_description/meshes/Rizon4s/visual/ring.obj" scale="0.051 0.051 0.002"/>
      </geometry>
    </visual>
    <collision name="convex_mesh">
      <origin rpy="0 0 0" xyz="0 0 0"/>
      <geometry>
        <mesh filename="package://flexiv_description/meshes/Rizon4s/collision/link3.stl"/>
      </geometry>
    </collision>
  </link>
  <link name="link4">
    <inertial>
      <mass value="2.4"/>
      <origin rpy="0 0 0" xyz="-0.01 0.03 0.1"/>
      <inertia ixx="0.02" ixy="0.0" ixz="-0.002" iyy="0.02" iyz="-0.001" izz="0.003"/>
    </inertial>
    <visual name="shell">
      <origin rpy="0 0 0" xyz="0 0 0"/>
      <geometry>
        <mesh filename="package://flexiv_description/meshes/Rizon4s/visual/link4.obj"/>
      </geometry>
    </visual>
    <visual name="ring">
      <origin rpy="1.5707963267948966 0 0" xyz="0 -0.0025 0"/>
      <geometry>
        <mesh filename="package://flexiv_description/meshes/Rizon4s/visual/ring.obj" scale="0.051 0.051 0.002"/>
      </geometry>
    </visual>
    <collision name="convex_mesh">
      <origin rpy="0 0 0" xyz="0 0 0"/>
      <geometry>
        <mesh filename="package://flexiv_description/meshes/Rizon4s/collision/link4.stl"/>
      </geometry>
    </collision>
  </link>
  <link name="link5">
    <inertial>
      <mass value="2.3"/>
      <origin rpy="0 0 0" xyz="0.0 0.0 0.14"/>
      <inertia ixx="0.01" ixy="0.0" ixz="0.0" iyy="0.01" iyz="0.001" izz="0.004"/>
    </inertial>
    <visual name="shell">
      <origin rpy="0 0 0" xyz="0 0 0"/>
      <geometry>
        <mesh filename="package://flexiv_description/meshes/Rizon4s/visual/link5.obj"/>
      </geometry>
    </visual>
    <visual name="ring">
      <origin rpy="0 0 0" xyz="0 0 -0.0025"/>
      <geometry>
        <mesh filename="package://flexiv_description/meshes/Rizon4s/visual/ring.obj" scale="0.051 0.051 0.002"/>
      </geometry>
    </visual>
    <collision name="convex_mesh">
      <origin rpy="0 0 0" xyz="0 0 0"/>
      <geometry>
        <mesh filename="package://flexiv_description/meshes/Rizon4s/collision/link5.stl"/>
      </geometry>
    </collision>
  </link>
  <link name="link6">
    <inertial>
      <mass value="2.2"/>
      <origin rpy="0 0 0" xyz="0.02 0.06 0.07"/>
      <inertia ixx="0.01" ixy="0.0" ixz="-0.001" iyy="0.01" iyz="0.002" izz="0.004"/>
    </inertial>
    <visual name="shell">
      <origin rpy="0 0 0" xyz="0 0 0"/>
      <geometry>
        <mesh filename="package://flexiv_description/meshes/Rizon4s/visual/link6.obj"/>
      </geometry>
    </visual>
    <visual name="ring">
      <origin rpy="1.5707963267948966 0 0" xyz="0 -0.0025 0"/>
      <geometry>
        <mesh filename="package://flexiv_description/meshes/Rizon4s/visual/ring.obj" scale="0.051 0.051 0.002"/>
      </geometry>
    </visual>
    <collision name="convex_mesh">
      <origin rpy="0 0 0" xyz="0 0 0"/>
      <geometry>
        <mesh filename="package://flexiv_description/meshes/Rizon4s/collision/link6.stl"/>
      </geometry>
    </collision>
  </link>
  <link name="link7">
    <inertial>
      <mass value="1.4"/>
      <origin rpy="0 0 0" xyz="0.0 0.0 0.05"/>
      <inertia ixx="0.001" ixy="0.0" ixz="0.0" iyy="0.001" iyz="0.0" izz="0.001"/>
    </inertial>
    <visual name="shell">
      <origin rpy="0 0 0" xyz="0 0 0"/>
      <geometry>
        <mesh filename="package://flexiv_description/meshes/Rizon4s/visual/link7.obj"/>
      </geometry>
    </visual>
    <visual name="ring">
      <origin rpy="0 0 0" xyz="0 0 -0.0025"/>
      <geometry>
        <mesh filename="package://flexiv_description/meshes/Rizon4s/visual/ring.obj" scale="0.051 0.051 0.002"/>
      </geometry>
    </visual>
    <collision name="hull">
      <origin rpy="0 0 0" xyz="0 0 0"/>
      <geometry>
        <mesh filename="package://flexiv_description/meshes/Rizon4s/collision/link7.stl"/>
      </geometry>
    </collision>
  </link>
  <link name="flange">
    <inertial>
      <mass value="0.0"/>
      <origin rpy="0 0 0" xyz="0.0 0.0 0.0"/>
      <inertia ixx="0.0" ixy="0.0" ixz="0.0" iyy="0.0" iyz="0.0" izz="0.0"/>
    </inertial>
  </link>
  <link name="gripper_frame">
    <inertial>
      <mass value="0.01"/>
      <inertia ixx="0.0001" ixy="0.0" ixz="0.0" iyy="0.0001" iyz="0.0" izz="0.0001"/>
      <origin rpy="0 0 0" xyz="0 0 0"/>
    </inertial>
  </link>
  <joint name="gripper_joint" type="fixed">
    <origin rpy="0 0 0" xyz="0 0 0"/>
    <parent link="flange"/>
    <child link="gripper_frame"/>
  </joint>
  <ros2_control name="FlexivHardwareInterface" type="system">
    <hardware>
      <plugin>flexiv_hardware/FlexivHardwareInterface</plugin>
      <param name="robot_sn"></param>
      <param name="prefix">_</param>
    </hardware>
    <joint name="joint1">
      <command_interface name="position">
        <param name="min">-2.7925</param>
        <param name="max">2.7925</param>
      </command_interface>
      <command_interface name="velocity">
        <param name="min">-2.0944</param>
        <param name="max">2.0944</param>
      </command_interface>
      <command_interface name="effort"/>
      <state_interface name="position">
        <!-- initial position for the FakeSystem -->
        <param name="initial_value">0.0</param>
      </state_interface>
      <state_interface name="velocity"/>
      <state_interface name="effort"/>
    </joint>
    <joint name="joint2">
      <command_interface name="position">
        <param name="min">-2.2689</param>
        <param name="max">2.2689</param>
      </command_interface>
      <command_interface name="velocity">
        <param name="min">-2.0944</param>
        <param name="max">2.0944</param>
      </command_interface>
      <command_interface name="effort"/>
      <state_interface name="position">
        <!-- initial position for the FakeSystem -->
        <param name="initial_value">-0.69813</param>
      </state_interface>
      <state_interface name="velocity"/>
      <state_interface name="effort"/>
    </joint>
    <joint name="joint3">
      <command_interface name="position">
        <param name="min">-2.9671</param>
        <param name="max">2.9671</param>
      </command_interface>
      <command_interface name="velocity">
        <param name="min">-2.4435</param>
        <param name="max">2.4435</param>
      </command_interface>
      <command_interface name="effort"/>
      <state_interface name="position">
        <!-- initial position for the FakeSystem -->
        <param name="initial_value">0.0</param>
      </state_interface>
      <state_interface name="velocity"/>
      <state_interface name="effort"/>
    </joint>
    <joint name="joint4">
      <command_interface name="position">
        <param name="min">-1.8675</param>
        <param name="max">2.6878</param>
      </command_interface>
      <command_interface name="velocity">
        <param name="min">-2.4435</param>
        <param name="max">2.4435</param>
      </command_interface>
      <command_interface name="effort"/>
      <state_interface name="position">
        <!-- initial position for the FakeSystem -->
        <param name="initial_value">1.570796</param>
      </state_interface>
      <state_interface name="velocity"/>
      <state_interface name="effort"/>
    </joint>
    <joint name="joint5">
      <command_interface name="position">
        <param name="min">-2.9671</param>
        <param name="max">2.9671</param>
      </command_interface>
      <command_interface name="velocity">
        <param name="min">-4.8869</param>
        <param name="max">4.8869</param>
      </command_interface>
      <command_interface name="effort"/>
      <state_interface name="position">
        <!-- initial position for the FakeSystem -->
        <param name="initial_value">0.0</param>
      </state_interface>
      <state_interface name="velocity"/>
      <state_interface name="effort"/>
    </joint>
    <joint name="joint6">
      <command_interface name="position">
        <param name="min">-1.3963</param>
        <param name="max">4.5379</param>
      </command_interface>
      <command_interface name="velocity">
        <param name="min">-4.8869</param>
        <param name="max">4.8869</param>
      </command_interface>
      <command_interface name="effort"/>
      <state_interface name="position">
        <!-- initial position for the FakeSystem -->
        <param name="initial_value">0.69813</param>
      </state_interface>
      <state_interface name="velocity"/>
      <state_interface name="effort"/>
    </joint>
    <joint name="joint7">
      <command_interface name="position">
        <param name="min">-2.9671</param>
        <param name="max">2.9671</param>
      </command_interface>
      <command_interface name="velocity">
        <param name="min">-4.8869</param>
        <param name="max">4.8869</param>
      </command_interface>
      <command_interface name="effort"/>
      <state_interface name="position">
        <!-- initial position for the FakeSystem -->
        <param name="initial_value">0.0</param>
      </state_interface>
      <state_interface name="velocity"/>
      <state_interface name="effort"/>
    </joint>
    <!-- 18 digital IO ports (16 on control box + 2 inside the wrist connector) -->
    <gpio name="gpio">
      <command_interface name="digital_output_0"/>
      <command_interface name="digital_output_1"/>
      <command_interface name="digital_output_2"/>
      <command_interface name="digital_output_3"/>
      <command_interface name="digital_output_4"/>
      <command_interface name="digital_output_5"/>
      <command_interface name="digital_output_6"/>
      <command_interface name="digital_output_7"/>
      <command_interface name="digital_output_8"/>
      <command_interface name="digital_output_9"/>
      <command_interface name="digital_output_10"/>
      <command_interface name="digital_output_11"/>
      <command_interface name="digital_output_12"/>
      <command_interface name="digital_output_13"/>
      <command_interface name="digital_output_14"/>
      <command_interface name="digital_output_15"/>
      <command_interface name="digital_output_16"/>
      <command_interface name="digital_output_17"/>
      <state_interface name="digital_input_0"/>
      <state_interface name="digital_input_1"/>
      <state_interface name="digital_input_2"/>
      <state_interface name="digital_input_3"/>
      <state_interface name="digital_input_4"/>
      <state_interface name="digital_input_5"/>
      <state_interface name="digital_input_6"/>
      <state_interface name="digital_input_7"/>
      <state_interface name="digital_input_8"/>
      <state_interface name="digital_input_9"/>
      <state_interface name="digital_input_10"/>
      <state_interface name="digital_input_11"/>
      <state_interface name="digital_input_12"/>
      <state_interface name="digital_input_13"/>
      <state_interface name="digital_input_14"/>
      <state_interface name="digital_input_15"/>
      <state_interface name="digital_input_16"/>
      <state_interface name="digital_input_17"/>
    </gpio>
  </ros2_control>
</robot>